2023-08-27 22:55:16.287120 
 Traceback (most recent call last):
  File "D:\Documents\Python_course\homework\lesson17\task3_employees_v3.py", line 17, in __init__
    self.validate_email(email)
  File "D:\Documents\Python_course\homework\lesson17\task3_employees_v3.py", line 73, in validate_email
    raise EmailValidationError
exceptions.EmailValidationError
 

2023-08-27 22:55:16.292122 
 Traceback (most recent call last):
  File "D:\Documents\Python_course\homework\lesson17\task3_employees_v3.py", line 17, in __init__
    self.validate_email(email)
  File "D:\Documents\Python_course\homework\lesson17\task3_employees_v3.py", line 76, in validate_email
    raise EmailAlreadyExistsException
exceptions.EmailAlreadyExistsException
 

2023-08-27 22:55:16.293122 
 Traceback (most recent call last):
  File "D:\Documents\Python_course\homework\lesson17\task3_employees_v3.py", line 17, in __init__
    self.validate_email(email)
  File "D:\Documents\Python_course\homework\lesson17\task3_employees_v3.py", line 76, in validate_email
    raise EmailAlreadyExistsException
exceptions.EmailAlreadyExistsException
 

2023-08-27 22:55:16.293122 
 Traceback (most recent call last):
  File "D:\Documents\Python_course\homework\lesson17\task3_employees_v3.py", line 17, in __init__
    self.validate_email(email)
  File "D:\Documents\Python_course\homework\lesson17\task3_employees_v3.py", line 73, in validate_email
    raise EmailValidationError
exceptions.EmailValidationError
 

2023-08-27 22:55:16.293122 
 Traceback (most recent call last):
  File "D:\Documents\Python_course\homework\lesson17\task3_employees_v3.py", line 17, in __init__
    self.validate_email(email)
  File "D:\Documents\Python_course\homework\lesson17\task3_employees_v3.py", line 73, in validate_email
    raise EmailValidationError
exceptions.EmailValidationError
 

